Workbook
Name CADDRESS1CUSTOMERMAIN: #REF!
Name CCOUHEADCUSTOMERMAIN: #REF!
Name CCOUNTRYCUSTOMERMAIN: #REF!
Name CCUSTYPECUSTOMERMAIN: #REF!
Name CIDCUSTOMERMAIN: #REF!
Name CLOCALITYCUSTOMERMAIN: #REF!
Name CNAME1CUSTOMERMAIN: #REF!
Name CVATCATCUSTOMERMAIN: #REF!
Name CVATNOCUSTOMERMAIN: #REF!
Name CVATREFCUSTOMERMAIN: #REF!
Name CZIPCODECUSTOMERMAIN: #REF!

Sheet 2) BOB compta (completer-forcer
A1: Journal | B1: Annee | C1: Mois | D1: Date facture | E1: Echeance | F1: Piece | G1: Tiers | H1: Compte | I1: Communication | J1: Remarque | K1: Mnt.TVAC | L1: TVA | M1: Taux | N1: Mnt.HTVA | O1: Mnt.TVA | P1: Devise | Q1: Cours | R1: NOM | S1: Adresse | T1: Code Postal | U1: Localite | V1: Assujetti | W1: Numéro | X1: Email | Y1: Pdf | Z1: PERSONNEL | AA1: RCP_PERDEB | AB1: RCP_PERFIN | AC1: CLIENT
A2: =IF('1) Import fichier Remi (coller)'!D2="","",'1) Import fichier Remi (coller)'!D2) -> NCV | B2: =IF(A2="","",YEAR('1) Import fichier Remi (coller)'!F2)) -> 2026 | C2: =IF(A2="","",MONTH('1) Import fichier Remi (coller)'!F2)) -> 9 | D2: =IF(A2="","",'1) Import fichier Remi (coller)'!F2) -> 46281 | E2: =IF(A2="","",'1) Import fichier Remi (coller)'!G2) -> 46281 | F2: =IF(A2="","",'1) Import fichier Remi (coller)'!E2) -> 12260077 | G2: JPSFITEST | H2: =IF(A2="","",IF(ISERROR(VLOOKUP('1) Import fichier Remi (coller)'!K2&" - "&'1) Import fichier Remi (coller)'!L2,'Spécifique comptes'!$A:$G,1,FALSE))=TRUE,'1) Import fichier Remi (coller)'!V2,VLOOKUP('1) Import fichier Remi (coller)'!K2&" - "&'1) Import fichier Remi (coller)'!L2,'Spécifique comptes'!$A:$G,IF(LEFT('2) BOB compta (completer-forcer'!F2,2)="11",4,IF(LEFT('2) BOB compta (completer-forcer'!F2,2)="12",5,IF(LEFT('2) BOB compta (completer-forcer'!F2,2)="13",6,IF(LEFT('2) BOB compta (completer-forcer'!F2,2)="15",7,"Erreur Compte")))),FALSE))) -> 705099999 | I2: =IF(A2="","",IF(H2="70100000",'1) Import fichier Remi (coller)'!J2,'1) Import fichier Remi (coller)'!U2)) -> +++003/8260/07776+++ | J2: =IF(A2="","",'1) Import fichier Remi (coller)'!U2) -> +++003/8260/07776+++ | K2: =IF(A2="","",SUMIFS(N:N,A:A,A2,F:F,F2)+SUMIFS(O:O,A:A,A2,F:F,F2)) -> 28.74 | L2: =IF(A2="","",IF(LEFT(T2,1)="B","V","PRT")) -> V | M2: =IF(A2="","",'1) Import fichier Remi (coller)'!S2) -> 21 | N2: =IF($A2="","",IF(OR($A2="NCV",$A2="NC15"),-'1) Import fichier Remi (coller)'!R2,'1) Import fichier Remi (coller)'!R2)) -> 23.75 | O2: =IF($A2="","",IF(OR($A2="NCV",$A2="NC15"),-'1) Import fichier Remi (coller)'!T2,'1) Import fichier Remi (coller)'!T2)) -> 4.99 | R2: =IF($A2="","",IF(ISERROR(VLOOKUP(LEFT('1) Import fichier Remi (coller)'!$A2,9),'Concordance client liv et fact'!$A:$H,8,FALSE))=TRUE,VLOOKUP(LEFT('1) Import fichier Remi (coller)'!$A2,9)+0,'Clients R2'!$A:$CY,2,FALSE),VLOOKUP(VLOOKUP(LEFT('1) Import fichier Remi (coller)'!$A2,9),'Concordance client liv et fact'!$A:$H,7,FALSE)+0,'Clients R2'!$A:$CY,2,FALSE))) -> JPS FINANCIAL SRL | S2: =IF($A2="","",PROPER(IF(ISERROR(VLOOKUP(LEFT('1) Import fichier Remi (coller)'!$A2,9),'Concordance client liv et fact'!$A:$H,8,FALSE))=TRUE,VLOOKUP(LEFT('1) Import fichier Remi (coller)'!$A2,9)+0,'Clients R2'!$A:$CY,27,FALSE),VLOOKUP(VLOOKUP(LEFT('1) Import fichier Remi (coller)'!$A2,9),'Concordance client liv et fact'!$A:$H,7,FALSE)+0,'Clients R2'!$A:$CY,27,FALSE)))) -> Rue De Mont 213 | T2: =IF($A2="","",LEFT(UPPER(IF(ISERROR(VLOOKUP(LEFT('1) Import fichier Remi (coller)'!$A2,9),'Concordance client liv et fact'!$A:$H,8,FALSE))=TRUE,VLOOKUP(LEFT('1) Import fichier Remi (coller)'!$A2,9)+0,'Clients R2'!$A:$CY,28,FALSE),VLOOKUP(VLOOKUP(LEFT('1) Import fichier Remi (coller)'!$A2,9),'Concordance client liv et fact'!$A:$H,7,FALSE)+0,'Clients R2'!$A:$CY,28,FALSE))),2)&UPPER(IF(ISERROR(VLOOKUP(LEFT('1) Import fichier Remi (coller)'!$A2,9),'Concordance client liv et fact'!$A:$H,8,FALSE))=TRUE,VLOOKUP(LEFT('1) Import fichier Remi (coller)'!$A2,9)+0,'Clients R2'!$A:$CY,29,FALSE),VLOOKUP(VLOOKUP(LEFT('1) Import fichier Remi (coller)'!$A2,9),'Concordance client liv et fact'!$A:$H,7,FALSE)+0,'Clients R2'!$A:$CY,29,FALSE)))) -> B 4820 | U2: =IF($A2="","",PROPER(IF(ISERROR(VLOOKUP(LEFT('1) Import fichier Remi (coller)'!$A2,9),'Concordance client liv et fact'!$A:$H,8,FALSE))=TRUE,VLOOKUP(LEFT('1) Import fichier Remi (coller)'!$A2,9)+0,'Clients R2'!$A:$CY,30,FALSE),VLOOKUP(VLOOKUP(LEFT('1) Import fichier Remi (coller)'!$A2,9),'Concordance client liv et fact'!$A:$H,7,FALSE)+0,'Clients R2'!$A:$CY,30,FALSE)))) -> Dison | V2: =IF($A2="","",LEFT(UPPER(IF(ISERROR(VLOOKUP(LEFT('1) Import fichier Remi (coller)'!$A2,9),'Concordance client liv et fact'!$A:$H,8,FALSE))=TRUE,IF(VLOOKUP(LEFT('1) Import fichier Remi (coller)'!$A2,9)+0,'Clients R2'!$A:$CY,22,FALSE)=4,"NA",VLOOKUP(LEFT('1) Import fichier Remi (coller)'!$A2,9)+0,'Clients R2'!$A:$CY,3,FALSE)),IF(VLOOKUP(VLOOKUP(LEFT('1) Import fichier Remi (coller)'!$A2,9),'Concordance client liv et fact'!$A:$H,7,FALSE)+0,'Clients R2'!$A:$CY,22,FALSE)=4,"NA",VLOOKUP(VLOOKUP(LEFT('1) Import fichier Remi (coller)'!$A2,9),'Concordance client liv et fact'!$A:$H,7,FALSE)+0,'Clients R2'!$A:$CY,3,FALSE)))),2)) -> BE | X2: =IF($A2="","",IF(ISERROR(VLOOKUP(LEFT('1) Import fichier Remi (coller)'!$A2,9),'Concordance client liv et fact'!$A:$H,8,FALSE))=TRUE,VLOOKUP(LEFT('1) Import fichier Remi (coller)'!$A2,9)+0,'Clients R2'!$A:$CY,102,FALSE),VLOOKUP(VLOOKUP(LEFT('1) Import fichier Remi (coller)'!$A2,9),'Concordance client liv et fact'!$A:$H,7,FALSE)+0,'Clients R2'!$A:$CY,102,FALSE))) -> jpierresch@voo.be | Y2: CF11261601.PDF | Z2: =IF(A2="","",IF(OR(H2="705099999",H2="705001002"),VLOOKUP('1) Import fichier Remi (coller)'!J2,'Analytique personnel'!$A:$B,2,FALSE),"")) -> LLHOMME | AA2: =IF($A2="VE11","",IF(LEFT($H2,4)="7050","",IF('1) Import fichier Remi (coller)'!M2="","",'1) Import fichier Remi (coller)'!M2))) | AB2: =IF($A2="VE11","",IF(LEFT($H2,4)="7050","",IF('1) Import fichier Remi (coller)'!N2="","",'1) Import fichier Remi (coller)'!N2))) | AC2: =IF(A2="","",VLOOKUP(LEFT('1) Import fichier Remi (coller)'!A2,9)+0,'Concordance Client R2 BOB'!$B:$C,2,FALSE)) -> JPSFINANCI
A3: =IF('1) Import fichier Remi (coller)'!D3="","",'1) Import fichier Remi (coller)'!D3) -> NCV | B3: =IF(A3="","",YEAR('1) Import fichier Remi (coller)'!F3)) -> 2026 | C3: =IF(A3="","",MONTH('1) Import fichier Remi (coller)'!F3)) -> 9 | D3: =IF(A3="","",'1) Import fichier Remi (coller)'!F3) -> 46281 | E3: =IF(A3="","",'1) Import fichier Remi (coller)'!G3) -> 46281 | F3: =IF(A3="","",'1) Import fichier Remi (coller)'!E3) -> 12260078 | G3: =IF(A3="","",IF(ISERROR(VLOOKUP(LEFT('1) Import fichier Remi (coller)'!A3,9),'Concordance client liv et fact'!$A:$H,8,FALSE))=TRUE,'1) Import fichier Remi (coller)'!B3,VLOOKUP(LEFT('1) Import fichier Remi (coller)'!A3,9),'Concordance client liv et fact'!$A:$H,8,FALSE))) -> IVZINC | H3: =IF(A3="","",IF(ISERROR(VLOOKUP('1) Import fichier Remi (coller)'!K3&" - "&'1) Import fichier Remi (coller)'!L3,'Spécifique comptes'!$A:$G,1,FALSE))=TRUE,'1) Import fichier Remi (coller)'!V3,VLOOKUP('1) Import fichier Remi (coller)'!K3&" - "&'1) Import fichier Remi (coller)'!L3,'Spécifique comptes'!$A:$G,IF(LEFT('2) BOB compta (completer-forcer'!F3,2)="11",4,IF(LEFT('2) BOB compta (completer-forcer'!F3,2)="12",5,IF(LEFT('2) BOB compta (completer-forcer'!F3,2)="13",6,IF(LEFT('2) BOB compta (completer-forcer'!F3,2)="15",7,"Erreur Compte")))),FALSE))) -> 705099999 | I3: =IF(A3="","",IF(H3="70100000",'1) Import fichier Remi (coller)'!J3,'1) Import fichier Remi (coller)'!U3)) -> +++003/8260/07877+++ | J3: =IF(A3="","",'1) Import fichier Remi (coller)'!U3) -> +++003/8260/07877+++ | K3: =IF(A3="","",SUMIFS(N:N,A:A,A3,F:F,F3)+SUMIFS(O:O,A:A,A3,F:F,F3)) -> 28.74 | L3: =IF(A3="","",IF(LEFT(T3,1)="B","V","PRT")) -> V | M3: =IF(A3="","",'1) Import fichier Remi (coller)'!S3) -> 21 | N3: =IF($A3="","",IF(OR($A3="NCV",$A3="NC15"),-'1) Import fichier Remi (coller)'!R3,'1) Import fichier Remi (coller)'!R3)) -> 23.75 | O3: =IF($A3="","",IF(OR($A3="NCV",$A3="NC15"),-'1) Import fichier Remi (coller)'!T3,'1) Import fichier Remi (coller)'!T3)) -> 4.99 | R3: =IF($A3="","",IF(ISERROR(VLOOKUP(LEFT('1) Import fichier Remi (coller)'!$A3,9),'Concordance client liv et fact'!$A:$H,8,FALSE))=TRUE,VLOOKUP(LEFT('1) Import fichier Remi (coller)'!$A3,9)+0,'Clients R2'!$A:$CY,2,FALSE),VLOOKUP(VLOOKUP(LEFT('1) Import fichier Remi (coller)'!$A3,9),'Concordance client liv et fact'!$A:$H,7,FALSE)+0,'Clients R2'!$A:$CY,2,FALSE))) -> IV ZINC SRL | S3: =IF($A3="","",PROPER(IF(ISERROR(VLOOKUP(LEFT('1) Import fichier Remi (coller)'!$A3,9),'Concordance client liv et fact'!$A:$H,8,FALSE))=TRUE,VLOOKUP(LEFT('1) Import fichier Remi (coller)'!$A3,9)+0,'Clients R2'!$A:$CY,27,FALSE),VLOOKUP(VLOOKUP(LEFT('1) Import fichier Remi (coller)'!$A3,9),'Concordance client liv et fact'!$A:$H,7,FALSE)+0,'Clients R2'!$A:$CY,27,FALSE)))) -> Rue De L'Eperonnerie 21 | T3: =IF($A3="","",LEFT(UPPER(IF(ISERROR(VLOOKUP(LEFT('1) Import fichier Remi (coller)'!$A3,9),'Concordance client liv et fact'!$A:$H,8,FALSE))=TRUE,VLOOKUP(LEFT('1) Import fichier Remi (coller)'!$A3,9)+0,'Clients R2'!$A:$CY,28,FALSE),VLOOKUP(VLOOKUP(LEFT('1) Import fichier Remi (coller)'!$A3,9),'Concordance client liv et fact'!$A:$H,7,FALSE)+0,'Clients R2'!$A:$CY,28,FALSE))),2)&UPPER(IF(ISERROR(VLOOKUP(LEFT('1) Import fichier Remi (coller)'!$A3,9),'Concordance client liv et fact'!$A:$H,8,FALSE))=TRUE,VLOOKUP(LEFT('1) Import fichier Remi (coller)'!$A3,9)+0,'Clients R2'!$A:$CY,29,FALSE),VLOOKUP(VLOOKUP(LEFT('1) Import fichier Remi (coller)'!$A3,9),'Concordance client liv et fact'!$A:$H,7,FALSE)+0,'Clients R2'!$A:$CY,29,FALSE)))) -> B 4081 | U3: =IF($A3="","",PROPER(IF(ISERROR(VLOOKUP(LEFT('1) Import fichier Remi (coller)'!$A3,9),'Concordance client liv et fact'!$A:$H,8,FALSE))=TRUE,VLOOKUP(LEFT('1) Import fichier Remi (coller)'!$A3,9)+0,'Clients R2'!$A:$CY,30,FALSE),VLOOKUP(VLOOKUP(LEFT('1) Import fichier Remi (coller)'!$A3,9),'Concordance client liv et fact'!$A:$H,7,FALSE)+0,'Clients R2'!$A:$CY,30,FALSE)))) -> Milmort | V3: =IF($A3="","",LEFT(UPPER(IF(ISERROR(VLOOKUP(LEFT('1) Import fichier Remi (coller)'!$A3,9),'Concordance client liv et fact'!$A:$H,8,FALSE))=TRUE,IF(VLOOKUP(LEFT('1) Import fichier Remi (coller)'!$A3,9)+0,'Clients R2'!$A:$CY,22,FALSE)=4,"NA",VLOOKUP(LEFT('1) Import fichier Remi (coller)'!$A3,9)+0,'Clients R2'!$A:$CY,3,FALSE)),IF(VLOOKUP(VLOOKUP(LEFT('1) Import fichier Remi (coller)'!$A3,9),'Concordance client liv et fact'!$A:$H,7,FALSE)+0,'Clients R2'!$A:$CY,22,FALSE)=4,"NA",VLOOKUP(VLOOKUP(LEFT('1) Import fichier Remi (coller)'!$A3,9),'Concordance client liv et fact'!$A:$H,7,FALSE)+0,'Clients R2'!$A:$CY,3,FALSE)))),2)) -> BE | X3: =IF($A3="","",IF(ISERROR(VLOOKUP(LEFT('1) Import fichier Remi (coller)'!$A3,9),'Concordance client liv et fact'!$A:$H,8,FALSE))=TRUE,VLOOKUP(LEFT('1) Import fichier Remi (coller)'!$A3,9)+0,'Clients R2'!$A:$CY,102,FALSE),VLOOKUP(VLOOKUP(LEFT('1) Import fichier Remi (coller)'!$A3,9),'Concordance client liv et fact'!$A:$H,7,FALSE)+0,'Clients R2'!$A:$CY,102,FALSE))) -> comptabilite.sabanigroup@gmail.com | Y3: CF11261601.PDF | Z3: =IF(A3="","",IF(OR(H3="705099999",H3="705001002"),VLOOKUP('1) Import fichier Remi (coller)'!J3,'Analytique personnel'!$A:$B,2,FALSE),"")) -> LLHOMME | AA3: =IF($A3="VE11","",IF(LEFT($H3,4)="7050","",IF('1) Import fichier Remi (coller)'!M3="","",'1) Import fichier Remi (coller)'!M3))) | AB3: =IF($A3="VE11","",IF(LEFT($H3,4)="7050","",IF('1) Import fichier Remi (coller)'!N3="","",'1) Import fichier Remi (coller)'!N3))) | AC3: =IF(A3="","",VLOOKUP(LEFT('1) Import fichier Remi (coller)'!A3,9)+0,'Concordance Client R2 BOB'!$B:$C,2,FALSE)) -> IVZINC
A4: =IF('1) Import fichier Remi (coller)'!D4="","",'1) Import fichier Remi (coller)'!D4) -> VE11 | B4: =IF(A4="","",YEAR('1) Import fichier Remi (coller)'!F4)) -> 2026 | C4: =IF(A4="","",MONTH('1) Import fichier Remi (coller)'!F4)) -> 9 | D4: =IF(A4="","",'1) Import fichier Remi (coller)'!F4) -> 46281 | E4: =IF(A4="","",'1) Import fichier Remi (coller)'!G4) -> 46281 | F4: =IF(A4="","",'1) Import fichier Remi (coller)'!E4) -> 11261511 | G4: =IF(A4="","",IF(ISERROR(VLOOKUP(LEFT('1) Import fichier Remi (coller)'!A4,9),'Concordance client liv et fact'!$A:$H,8,FALSE))=TRUE,'1) Import fichier Remi (coller)'!B4,VLOOKUP(LEFT('1) Import fichier Remi (coller)'!A4,9),'Concordance client liv et fact'!$A:$H,8,FALSE))) -> IBS | H4: =IF(A4="","",IF(ISERROR(VLOOKUP('1) Import fichier Remi (coller)'!K4&" - "&'1) Import fichier Remi (coller)'!L4,'Spécifique comptes'!$A:$G,1,FALSE))=TRUE,'1) Import fichier Remi (coller)'!V4,VLOOKUP('1) Import fichier Remi (coller)'!K4&" - "&'1) Import fichier Remi (coller)'!L4,'Spécifique comptes'!$A:$G,IF(LEFT('2) BOB compta (completer-forcer'!F4,2)="11",4,IF(LEFT('2) BOB compta (completer-forcer'!F4,2)="12",5,IF(LEFT('2) BOB compta (completer-forcer'!F4,2)="13",6,IF(LEFT('2) BOB compta (completer-forcer'!F4,2)="15",7,"Erreur Compte")))),FALSE))) -> 705002000 | I4: =IF(A4="","",IF(H4="70100000",'1) Import fichier Remi (coller)'!J4,'1) Import fichier Remi (coller)'!U4)) -> +++003/7261/51128+++ | J4: =IF(A4="","",'1) Import fichier Remi (coller)'!U4) -> +++003/7261/51128+++ | K4: =IF(A4="","",SUMIFS(N:N,A:A,A4,F:F,F4)+SUMIFS(O:O,A:A,A4,F:F,F4)) -> 152.46 | L4: =IF(A4="","",IF(LEFT(T4,1)="B","V","PRT")) -> V | M4: =IF(A4="","",'1) Import fichier Remi (coller)'!S4) -> 21 | N4: =IF($A4="","",IF(OR($A4="NCV",$A4="NC15"),-'1) Import fichier Remi (coller)'!R4,'1) Import fichier Remi (coller)'!R4)) -> 18 | O4: =IF($A4="","",IF(OR($A4="NCV",$A4="NC15"),-'1) Import fichier Remi (coller)'!T4,'1) Import fichier Remi (coller)'!T4)) -> 3.78 | R4: =IF($A4="","",IF(ISERROR(VLOOKUP(LEFT('1) Import fichier Remi (coller)'!$A4,9),'Concordance client liv et fact'!$A:$H,8,FALSE))=TRUE,VLOOKUP(LEFT('1) Import fichier Remi (coller)'!$A4,9)+0,'Clients R2'!$A:$CY,2,FALSE),VLOOKUP(VLOOKUP(LEFT('1) Import fichier Remi (coller)'!$A4,9),'Concordance client liv et fact'!$A:$H,7,FALSE)+0,'Clients R2'!$A:$CY,2,FALSE))) -> IBGRAF BUSINESS SOL. | S4: =IF($A4="","",PROPER(IF(ISERROR(VLOOKUP(LEFT('1) Import fichier Remi (coller)'!$A4,9),'Concordance client liv et fact'!$A:$H,8,FALSE))=TRUE,VLOOKUP(LEFT('1) Import fichier Remi (coller)'!$A4,9)+0,'Clients R2'!$A:$CY,27,FALSE),VLOOKUP(VLOOKUP(LEFT('1) Import fichier Remi (coller)'!$A4,9),'Concordance client liv et fact'!$A:$H,7,FALSE)+0,'Clients R2'!$A:$CY,27,FALSE)))) -> Rue D'Abhooz, 27 | T4: =IF($A4="","",LEFT(UPPER(IF(ISERROR(VLOOKUP(LEFT('1) Import fichier Remi (coller)'!$A4,9),'Concordance client liv et fact'!$A:$H,8,FALSE))=TRUE,VLOOKUP(LEFT('1) Import fichier Remi (coller)'!$A4,9)+0,'Clients R2'!$A:$CY,28,FALSE),VLOOKUP(VLOOKUP(LEFT('1) Import fichier Remi (coller)'!$A4,9),'Concordance client liv et fact'!$A:$H,7,FALSE)+0,'Clients R2'!$A:$CY,28,FALSE))),2)&UPPER(IF(ISERROR(VLOOKUP(LEFT('1) Import fichier Remi (coller)'!$A4,9),'Concordance client liv et fact'!$A:$H,8,FALSE))=TRUE,VLOOKUP(LEFT('1) Import fichier Remi (coller)'!$A4,9)+0,'Clients R2'!$A:$CY,29,FALSE),VLOOKUP(VLOOKUP(LEFT('1) Import fichier Remi (coller)'!$A4,9),'Concordance client liv et fact'!$A:$H,7,FALSE)+0,'Clients R2'!$A:$CY,29,FALSE)))) -> B 4040 | U4: =IF($A4="","",PROPER(IF(ISERROR(VLOOKUP(LEFT('1) Import fichier Remi (coller)'!$A4,9),'Concordance client liv et fact'!$A:$H,8,FALSE))=TRUE,VLOOKUP(LEFT('1) Import fichier Remi (coller)'!$A4,9)+0,'Clients R2'!$A:$CY,30,FALSE),VLOOKUP(VLOOKUP(LEFT('1) Import fichier Remi (coller)'!$A4,9),'Concordance client liv et fact'!$A:$H,7,FALSE)+0,'Clients R2'!$A:$CY,30,FALSE)))) -> Herstal | V4: =IF($A4="","",LEFT(UPPER(IF(ISERROR(VLOOKUP(LEFT('1) Import fichier Remi (coller)'!$A4,9),'Concordance client liv et fact'!$A:$H,8,FALSE))=TRUE,IF(VLOOKUP(LEFT('1) Import fichier Remi (coller)'!$A4,9)+0,'Clients R2'!$A:$CY,22,FALSE)=4,"NA",VLOOKUP(LEFT('1) Import fichier Remi (coller)'!$A4,9)+0,'Clients R2'!$A:$CY,3,FALSE)),IF(VLOOKUP(VLOOKUP(LEFT('1) Import fichier Remi (coller)'!$A4,9),'Concordance client liv et fact'!$A:$H,7,FALSE)+0,'Clients R2'!$A:$CY,22,FALSE)=4,"NA",VLOOKUP(VLOOKUP(LEFT('1) Import fichier Remi (coller)'!$A4,9),'Concordance client liv et fact'!$A:$H,7,FALSE)+0,'Clients R2'!$A:$CY,3,FALSE)))),2)) -> BE | X4: =IF($A4="","",IF(ISERROR(VLOOKUP(LEFT('1) Import fichier Remi (coller)'!$A4,9),'Concordance client liv et fact'!$A:$H,8,FALSE))=TRUE,VLOOKUP(LEFT('1) Import fichier Remi (coller)'!$A4,9)+0,'Clients R2'!$A:$CY,102,FALSE),VLOOKUP(VLOOKUP(LEFT('1) Import fichier Remi (coller)'!$A4,9),'Concordance client liv et fact'!$A:$H,7,FALSE)+0,'Clients R2'!$A:$CY,102,FALSE))) -> compta.ibs@ibgraf.com | Y4: CF11261601.PDF | Z4: BMELIN | AA4: =IF($A4="VE11","",IF(LEFT($H4,4)="7050","",IF('1) Import fichier Remi (coller)'!M4="","",'1) Import fichier Remi (coller)'!M4))) | AB4: =IF($A4="VE11","",IF(LEFT($H4,4)="7050","",IF('1) Import fichier Remi (coller)'!N4="","",'1) Import fichier Remi (coller)'!N4))) | AC4: =IF(A4="","",VLOOKUP(LEFT('1) Import fichier Remi (coller)'!A4,9)+0,'Concordance Client R2 BOB'!$B:$C,2,FALSE)) -> IBS
A5: =IF('1) Import fichier Remi (coller)'!D5="","",'1) Import fichier Remi (coller)'!D5) -> VE11 | B5: =IF(A5="","",YEAR('1) Import fichier Remi (coller)'!F5)) -> 2026 | C5: =IF(A5="","",MONTH('1) Import fichier Remi (coller)'!F5)) -> 9 | D5: =IF(A5="","",'1) Import fichier Remi (coller)'!F5) -> 46281 | E5: =IF(A5="","",'1) Import fichier Remi (coller)'!G5) -> 46281 | F5: =IF(A5="","",'1) Import fichier Remi (coller)'!E5) -> 11261511 | G5: =IF(A5="","",IF(ISERROR(VLOOKUP(LEFT('1) Import fichier Remi (coller)'!A5,9),'Concordance client liv et fact'!$A:$H,8,FALSE))=TRUE,'1) Import fichier Remi (coller)'!B5,VLOOKUP(LEFT('1) Import fichier Remi (coller)'!A5,9),'Concordance client liv et fact'!$A:$H,8,FALSE))) -> IBS | H5: =IF(A5="","",IF(ISERROR(VLOOKUP('1) Import fichier Remi (coller)'!K5&" - "&'1) Import fichier Remi (coller)'!L5,'Spécifique comptes'!$A:$G,1,FALSE))=TRUE,'1) Import fichier Remi (coller)'!V5,VLOOKUP('1) Import fichier Remi (coller)'!K5&" - "&'1) Import fichier Remi (coller)'!L5,'Spécifique comptes'!$A:$G,IF(LEFT('2) BOB compta (completer-forcer'!F5,2)="11",4,IF(LEFT('2) BOB compta (completer-forcer'!F5,2)="12",5,IF(LEFT('2) BOB compta (completer-forcer'!F5,2)="13",6,IF(LEFT('2) BOB compta (completer-forcer'!F5,2)="15",7,"Erreur Compte")))),FALSE))) -> 705002000 | I5: =IF(A5="","",IF(H5="70100000",'1) Import fichier Remi (coller)'!J5,'1) Import fichier Remi (coller)'!U5)) -> +++003/7261/51128+++ | J5: =IF(A5="","",'1) Import fichier Remi (coller)'!U5) -> +++003/7261/51128+++ | K5: =IF(A5="","",SUMIFS(N:N,A:A,A5,F:F,F5)+SUMIFS(O:O,A:A,A5,F:F,F5)) -> 152.46 | L5: =IF(A5="","",IF(LEFT(T5,1)="B","V","PRT")) -> V | M5: =IF(A5="","",'1) Import fichier Remi (coller)'!S5) -> 21 | N5: =IF($A5="","",IF(OR($A5="NCV",$A5="NC15"),-'1) Import fichier Remi (coller)'!R5,'1) Import fichier Remi (coller)'!R5)) -> 72 | O5: =IF($A5="","",IF(OR($A5="NCV",$A5="NC15"),-'1) Import fichier Remi (coller)'!T5,'1) Import fichier Remi (coller)'!T5)) -> 15.12 | R5: =IF($A5="","",IF(ISERROR(VLOOKUP(LEFT('1) Import fichier Remi (coller)'!$A5,9),'Concordance client liv et fact'!$A:$H,8,FALSE))=TRUE,VLOOKUP(LEFT('1) Import fichier Remi (coller)'!$A5,9)+0,'Clients R2'!$A:$CY,2,FALSE),VLOOKUP(VLOOKUP(LEFT('1) Import fichier Remi (coller)'!$A5,9),'Concordance client liv et fact'!$A:$H,7,FALSE)+0,'Clients R2'!$A:$CY,2,FALSE))) -> IBGRAF BUSINESS SOL. | S5: =IF($A5="","",PROPER(IF(ISERROR(VLOOKUP(LEFT('1) Import fichier Remi (coller)'!$A5,9),'Concordance client liv et fact'!$A:$H,8,FALSE))=TRUE,VLOOKUP(LEFT('1) Import fichier Remi (coller)'!$A5,9)+0,'Clients R2'!$A:$CY,27,FALSE),VLOOKUP(VLOOKUP(LEFT('1) Import fichier Remi (coller)'!$A5,9),'Concordance client liv et fact'!$A:$H,7,FALSE)+0,'Clients R2'!$A:$CY,27,FALSE)))) -> Rue D'Abhooz, 27 | T5: =IF($A5="","",LEFT(UPPER(IF(ISERROR(VLOOKUP(LEFT('1) Import fichier Remi (coller)'!$A5,9),'Concordance client liv et fact'!$A:$H,8,FALSE))=TRUE,VLOOKUP(LEFT('1) Import fichier Remi (coller)'!$A5,9)+0,'Clients R2'!$A:$CY,28,FALSE),VLOOKUP(VLOOKUP(LEFT('1) Import fichier Remi (coller)'!$A5,9),'Concordance client liv et fact'!$A:$H,7,FALSE)+0,'Clients R2'!$A:$CY,28,FALSE))),2)&UPPER(IF(ISERROR(VLOOKUP(LEFT('1) Import fichier Remi (coller)'!$A5,9),'Concordance client liv et fact'!$A:$H,8,FALSE))=TRUE,VLOOKUP(LEFT('1) Import fichier Remi (coller)'!$A5,9)+0,'Clients R2'!$A:$CY,29,FALSE),VLOOKUP(VLOOKUP(LEFT('1) Import fichier Remi (coller)'!$A5,9),'Concordance client liv et fact'!$A:$H,7,FALSE)+0,'Clients R2'!$A:$CY,29,FALSE)))) -> B 4040 | U5: =IF($A5="","",PROPER(IF(ISERROR(VLOOKUP(LEFT('1) Import fichier Remi (coller)'!$A5,9),'Concordance client liv et fact'!$A:$H,8,FALSE))=TRUE,VLOOKUP(LEFT('1) Import fichier Remi (coller)'!$A5,9)+0,'Clients R2'!$A:$CY,30,FALSE),VLOOKUP(VLOOKUP(LEFT('1) Import fichier Remi (coller)'!$A5,9),'Concordance client liv et fact'!$A:$H,7,FALSE)+0,'Clients R2'!$A:$CY,30,FALSE)))) -> Herstal | V5: =IF($A5="","",LEFT(UPPER(IF(ISERROR(VLOOKUP(LEFT('1) Import fichier Remi (coller)'!$A5,9),'Concordance client liv et fact'!$A:$H,8,FALSE))=TRUE,IF(VLOOKUP(LEFT('1) Import fichier Remi (coller)'!$A5,9)+0,'Clients R2'!$A:$CY,22,FALSE)=4,"NA",VLOOKUP(LEFT('1) Import fichier Remi (coller)'!$A5,9)+0,'Clients R2'!$A:$CY,3,FALSE)),IF(VLOOKUP(VLOOKUP(LEFT('1) Import fichier Remi (coller)'!$A5,9),'Concordance client liv et fact'!$A:$H,7,FALSE)+0,'Clients R2'!$A:$CY,22,FALSE)=4,"NA",VLOOKUP(VLOOKUP(LEFT('1) Import fichier Remi (coller)'!$A5,9),'Concordance client liv et fact'!$A:$H,7,FALSE)+0,'Clients R2'!$A:$CY,3,FALSE)))),2)) -> BE | X5: =IF($A5="","",IF(ISERROR(VLOOKUP(LEFT('1) Import fichier Remi (coller)'!$A5,9),'Concordance client liv et fact'!$A:$H,8,FALSE))=TRUE,VLOOKUP(LEFT('1) Import fichier Remi (coller)'!$A5,9)+0,'Clients R2'!$A:$CY,102,FALSE),VLOOKUP(VLOOKUP(LEFT('1) Import fichier Remi (coller)'!$A5,9),'Concordance client liv et fact'!$A:$H,7,FALSE)+0,'Clients R2'!$A:$CY,102,FALSE))) -> compta.ibs@ibgraf.com | Y5: CF11261601.PDF | Z5: BMELIN | AA5: =IF($A5="VE11","",IF(LEFT($H5,4)="7050","",IF('1) Import fichier Remi (coller)'!M5="","",'1) Import fichier Remi (coller)'!M5))) | AB5: =IF($A5="VE11","",IF(LEFT($H5,4)="7050","",IF('1) Import fichier Remi (coller)'!N5="","",'1) Import fichier Remi (coller)'!N5))) | AC5: =IF(A5="","",VLOOKUP(LEFT('1) Import fichier Remi (coller)'!A5,9)+0,'Concordance Client R2 BOB'!$B:$C,2,FALSE)) -> IBS
A6: =IF('1) Import fichier Remi (coller)'!D6="","",'1) Import fichier Remi (coller)'!D6) -> VE11 | B6: =IF(A6="","",YEAR('1) Import fichier Remi (coller)'!F6)) -> 2026 | C6: =IF(A6="","",MONTH('1) Import fichier Remi (coller)'!F6)) -> 9 | D6: =IF(A6="","",'1) Import fichier Remi (coller)'!F6) -> 46281 | E6: =IF(A6="","",'1) Import fichier Remi (coller)'!G6) -> 46281 | F6: =IF(A6="","",'1) Import fichier Remi (coller)'!E6) -> 11261511 | G6: =IF(A6="","",IF(ISERROR(VLOOKUP(LEFT('1) Import fichier Remi (coller)'!A6,9),'Concordance client liv et fact'!$A:$H,8,FALSE))=TRUE,'1) Import fichier Remi (coller)'!B6,VLOOKUP(LEFT('1) Import fichier Remi (coller)'!A6,9),'Concordance client liv et fact'!$A:$H,8,FALSE))) -> IBS | H6: =IF(A6="","",IF(ISERROR(VLOOKUP('1) Import fichier Remi (coller)'!K6&" - "&'1) Import fichier Remi (coller)'!L6,'Spécifique comptes'!$A:$G,1,FALSE))=TRUE,'1) Import fichier Remi (coller)'!V6,VLOOKUP('1) Import fichier Remi (coller)'!K6&" - "&'1) Import fichier Remi (coller)'!L6,'Spécifique comptes'!$A:$G,IF(LEFT('2) BOB compta (completer-forcer'!F6,2)="11",4,IF(LEFT('2) BOB compta (completer-forcer'!F6,2)="12",5,IF(LEFT('2) BOB compta (completer-forcer'!F6,2)="13",6,IF(LEFT('2) BOB compta (completer-forcer'!F6,2)="15",7,"Erreur Compte")))),FALSE))) -> 705002000 | I6: =IF(A6="","",IF(H6="70100000",'1) Import fichier Remi (coller)'!J6,'1) Import fichier Remi (coller)'!U6)) -> +++003/7261/51128+++ | J6: =IF(A6="","",'1) Import fichier Remi (coller)'!U6) -> +++003/7261/51128+++ | K6: =IF(A6="","",SUMIFS(N:N,A:A,A6,F:F,F6)+SUMIFS(O:O,A:A,A6,F:F,F6)) -> 152.46 | L6: =IF(A6="","",IF(LEFT(T6,1)="B","V","PRT")) -> V | M6: =IF(A6="","",'1) Import fichier Remi (coller)'!S6) -> 21 | N6: =IF($A6="","",IF(OR($A6="NCV",$A6="NC15"),-'1) Import fichier Remi (coller)'!R6,'1) Import fichier Remi (coller)'!R6)) -> 18 | O6: =IF($A6="","",IF(OR($A6="NCV",$A6="NC15"),-'1) Import fichier Remi (coller)'!T6,'1) Import fichier Remi (coller)'!T6)) -> 3.78 | R6: =IF($A6="","",IF(ISERROR(VLOOKUP(LEFT('1) Import fichier Remi (coller)'!$A6,9),'Concordance client liv et fact'!$A:$H,8,FALSE))=TRUE,VLOOKUP(LEFT('1) Import fichier Remi (coller)'!$A6,9)+0,'Clients R2'!$A:$CY,2,FALSE),VLOOKUP(VLOOKUP(LEFT('1) Import fichier Remi (coller)'!$A6,9),'Concordance client liv et fact'!$A:$H,7,FALSE)+0,'Clients R2'!$A:$CY,2,FALSE))) -> IBGRAF BUSINESS SOL. | S6: =IF($A6="","",PROPER(IF(ISERROR(VLOOKUP(LEFT('1) Import fichier Remi (coller)'!$A6,9),'Concordance client liv et fact'!$A:$H,8,FALSE))=TRUE,VLOOKUP(LEFT('1) Import fichier Remi (coller)'!$A6,9)+0,'Clients R2'!$A:$CY,27,FALSE),VLOOKUP(VLOOKUP(LEFT('1) Import fichier Remi (coller)'!$A6,9),'Concordance client liv et fact'!$A:$H,7,FALSE)+0,'Clients R2'!$A:$CY,27,FALSE)))) -> Rue D'Abhooz, 27 | T6: =IF($A6="","",LEFT(UPPER(IF(ISERROR(VLOOKUP(LEFT('1) Import fichier Remi (coller)'!$A6,9),'Concordance client liv et fact'!$A:$H,8,FALSE))=TRUE,VLOOKUP(LEFT('1) Import fichier Remi (coller)'!$A6,9)+0,'Clients R2'!$A:$CY,28,FALSE),VLOOKUP(VLOOKUP(LEFT('1) Import fichier Remi (coller)'!$A6,9),'Concordance client liv et fact'!$A:$H,7,FALSE)+0,'Clients R2'!$A:$CY,28,FALSE))),2)&UPPER(IF(ISERROR(VLOOKUP(LEFT('1) Import fichier Remi (coller)'!$A6,9),'Concordance client liv et fact'!$A:$H,8,FALSE))=TRUE,VLOOKUP(LEFT('1) Import fichier Remi (coller)'!$A6,9)+0,'Clients R2'!$A:$CY,29,FALSE),VLOOKUP(VLOOKUP(LEFT('1) Import fichier Remi (coller)'!$A6,9),'Concordance client liv et fact'!$A:$H,7,FALSE)+0,'Clients R2'!$A:$CY,29,FALSE)))) -> B 4040 | U6: =IF($A6="","",PROPER(IF(ISERROR(VLOOKUP(LEFT('1) Import fichier Remi (coller)'!$A6,9),'Concordance client liv et fact'!$A:$H,8,FALSE))=TRUE,VLOOKUP(LEFT('1) Import fichier Remi (coller)'!$A6,9)+0,'Clients R2'!$A:$CY,30,FALSE),VLOOKUP(VLOOKUP(LEFT('1) Import fichier Remi (coller)'!$A6,9),'Concordance client liv et fact'!$A:$H,7,FALSE)+0,'Clients R2'!$A:$CY,30,FALSE)))) -> Herstal | V6: =IF($A6="","",LEFT(UPPER(IF(ISERROR(VLOOKUP(LEFT('1) Import fichier Remi (coller)'!$A6,9),'Concordance client liv et fact'!$A:$H,8,FALSE))=TRUE,IF(VLOOKUP(LEFT('1) Import fichier Remi (coller)'!$A6,9)+0,'Clients R2'!$A:$CY,22,FALSE)=4,"NA",VLOOKUP(LEFT('1) Import fichier Remi (coller)'!$A6,9)+0,'Clients R2'!$A:$CY,3,FALSE)),IF(VLOOKUP(VLOOKUP(LEFT('1) Import fichier Remi (coller)'!$A6,9),'Concordance client liv et fact'!$A:$H,7,FALSE)+0,'Clients R2'!$A:$CY,22,FALSE)=4,"NA",VLOOKUP(VLOOKUP(LEFT('1) Import fichier Remi (coller)'!$A6,9),'Concordance client liv et fact'!$A:$H,7,FALSE)+0,'Clients R2'!$A:$CY,3,FALSE)))),2)) -> BE | X6: =IF($A6="","",IF(ISERROR(VLOOKUP(LEFT('1) Import fichier Remi (coller)'!$A6,9),'Concordance client liv et fact'!$A:$H,8,FALSE))=TRUE,VLOOKUP(LEFT('1) Import fichier Remi (coller)'!$A6,9)+0,'Clients R2'!$A:$CY,102,FALSE),VLOOKUP(VLOOKUP(LEFT('1) Import fichier Remi (coller)'!$A6,9),'Concordance client liv et fact'!$A:$H,7,FALSE)+0,'Clients R2'!$A:$CY,102,FALSE))) -> compta.ibs@ibgraf.com | Y6: CF11261601.PDF | Z6: GDUHOUX | AA6: =IF($A6="VE11","",IF(LEFT($H6,4)="7050","",IF('1) Import fichier Remi (coller)'!M6="","",'1) Import fichier Remi (coller)'!M6))) | AB6: =IF($A6="VE11","",IF(LEFT($H6,4)="7050","",IF('1) Import fichier Remi (coller)'!N6="","",'1) Import fichier Remi (coller)'!N6))) | AC6: =IF(A6="","",VLOOKUP(LEFT('1) Import fichier Remi (coller)'!A6,9)+0,'Concordance Client R2 BOB'!$B:$C,2,FALSE)) -> IBS
A7: =IF('1) Import fichier Remi (coller)'!D7="","",'1) Import fichier Remi (coller)'!D7) -> VE11 | B7: =IF(A7="","",YEAR('1) Import fichier Remi (coller)'!F7)) -> 2026 | C7: =IF(A7="","",MONTH('1) Import fichier Remi (coller)'!F7)) -> 9 | D7: =IF(A7="","",'1) Import fichier Remi (coller)'!F7) -> 46281 | E7: =IF(A7="","",'1) Import fichier Remi (coller)'!G7) -> 46281 | F7: =IF(A7="","",'1) Import fichier Remi (coller)'!E7) -> 11261511 | G7: =IF(A7="","",IF(ISERROR(VLOOKUP(LEFT('1) Import fichier Remi (coller)'!A7,9),'Concordance client liv et fact'!$A:$H,8,FALSE))=TRUE,'1) Import fichier Remi (coller)'!B7,VLOOKUP(LEFT('1) Import fichier Remi (coller)'!A7,9),'Concordance client liv et fact'!$A:$H,8,FALSE))) -> IBS | H7: =IF(A7="","",IF(ISERROR(VLOOKUP('1) Import fichier Remi (coller)'!K7&" - "&'1) Import fichier Remi (coller)'!L7,'Spécifique comptes'!$A:$G,1,FALSE))=TRUE,'1) Import fichier Remi (coller)'!V7,VLOOKUP('1) Import fichier Remi (coller)'!K7&" - "&'1) Import fichier Remi (coller)'!L7,'Spécifique comptes'!$A:$G,IF(LEFT('2) BOB compta (completer-forcer'!F7,2)="11",4,IF(LEFT('2) BOB compta (completer-forcer'!F7,2)="12",5,IF(LEFT('2) BOB compta (completer-forcer'!F7,2)="13",6,IF(LEFT('2) BOB compta (completer-forcer'!F7,2)="15",7,"Erreur Compte")))),FALSE))) -> 705002000 | I7: =IF(A7="","",IF(H7="70100000",'1) Import fichier Remi (coller)'!J7,'1) Import fichier Remi (coller)'!U7)) -> +++003/7261/51128+++ | J7: =IF(A7="","",'1) Import fichier Remi (coller)'!U7) -> +++003/7261/51128+++ | K7: =IF(A7="","",SUMIFS(N:N,A:A,A7,F:F,F7)+SUMIFS(O:O,A:A,A7,F:F,F7)) -> 152.46 | L7: =IF(A7="","",IF(LEFT(T7,1)="B","V","PRT")) -> V | M7: =IF(A7="","",'1) Import fichier Remi (coller)'!S7) -> 21 | N7: =IF($A7="","",IF(OR($A7="NCV",$A7="NC15"),-'1) Import fichier Remi (coller)'!R7,'1) Import fichier Remi (coller)'!R7)) -> 18 | O7: =IF($A7="","",IF(OR($A7="NCV",$A7="NC15"),-'1) Import fichier Remi (coller)'!T7,'1) Import fichier Remi (coller)'!T7)) -> 3.78 | R7: =IF($A7="","",IF(ISERROR(VLOOKUP(LEFT('1) Import fichier Remi (coller)'!$A7,9),'Concordance client liv et fact'!$A:$H,8,FALSE))=TRUE,VLOOKUP(LEFT('1) Import fichier Remi (coller)'!$A7,9)+0,'Clients R2'!$A:$CY,2,FALSE),VLOOKUP(VLOOKUP(LEFT('1) Import fichier Remi (coller)'!$A7,9),'Concordance client liv et fact'!$A:$H,7,FALSE)+0,'Clients R2'!$A:$CY,2,FALSE))) -> IBGRAF BUSINESS SOL. | S7: =IF($A7="","",PROPER(IF(ISERROR(VLOOKUP(LEFT('1) Import fichier Remi (coller)'!$A7,9),'Concordance client liv et fact'!$A:$H,8,FALSE))=TRUE,VLOOKUP(LEFT('1) Import fichier Remi (coller)'!$A7,9)+0,'Clients R2'!$A:$CY,27,FALSE),VLOOKUP(VLOOKUP(LEFT('1) Import fichier Remi (coller)'!$A7,9),'Concordance client liv et fact'!$A:$H,7,FALSE)+0,'Clients R2'!$A:$CY,27,FALSE)))) -> Rue D'Abhooz, 27 | T7: =IF($A7="","",LEFT(UPPER(IF(ISERROR(VLOOKUP(LEFT('1) Import fichier Remi (coller)'!$A7,9),'Concordance client liv et fact'!$A:$H,8,FALSE))=TRUE,VLOOKUP(LEFT('1) Import fichier Remi (coller)'!$A7,9)+0,'Clients R2'!$A:$CY,28,FALSE),VLOOKUP(VLOOKUP(LEFT('1) Import fichier Remi (coller)'!$A7,9),'Concordance client liv et fact'!$A:$H,7,FALSE)+0,'Clients R2'!$A:$CY,28,FALSE))),2)&UPPER(IF(ISERROR(VLOOKUP(LEFT('1) Import fichier Remi (coller)'!$A7,9),'Concordance client liv et fact'!$A:$H,8,FALSE))=TRUE,VLOOKUP(LEFT('1) Import fichier Remi (coller)'!$A7,9)+0,'Clients R2'!$A:$CY,29,FALSE),VLOOKUP(VLOOKUP(LEFT('1) Import fichier Remi (coller)'!$A7,9),'Concordance client liv et fact'!$A:$H,7,FALSE)+0,'Clients R2'!$A:$CY,29,FALSE)))) -> B 4040 | U7: =IF($A7="","",PROPER(IF(ISERROR(VLOOKUP(LEFT('1) Import fichier Remi (coller)'!$A7,9),'Concordance client liv et fact'!$A:$H,8,FALSE))=TRUE,VLOOKUP(LEFT('1) Import fichier Remi (coller)'!$A7,9)+0,'Clients R2'!$A:$CY,30,FALSE),VLOOKUP(VLOOKUP(LEFT('1) Import fichier Remi (coller)'!$A7,9),'Concordance client liv et fact'!$A:$H,7,FALSE)+0,'Clients R2'!$A:$CY,30,FALSE)))) -> Herstal | V7: =IF($A7="","",LEFT(UPPER(IF(ISERROR(VLOOKUP(LEFT('1) Import fichier Remi (coller)'!$A7,9),'Concordance client liv et fact'!$A:$H,8,FALSE))=TRUE,IF(VLOOKUP(LEFT('1) Import fichier Remi (coller)'!$A7,9)+0,'Clients R2'!$A:$CY,22,FALSE)=4,"NA",VLOOKUP(LEFT('1) Import fichier Remi (coller)'!$A7,9)+0,'Clients R2'!$A:$CY,3,FALSE)),IF(VLOOKUP(VLOOKUP(LEFT('1) Import fichier Remi (coller)'!$A7,9),'Concordance client liv et fact'!$A:$H,7,FALSE)+0,'Clients R2'!$A:$CY,22,FALSE)=4,"NA",VLOOKUP(VLOOKUP(LEFT('1) Import fichier Remi (coller)'!$A7,9),'Concordance client liv et fact'!$A:$H,7,FALSE)+0,'Clients R2'!$A:$CY,3,FALSE)))),2)) -> BE | X7: =IF($A7="","",IF(ISERROR(VLOOKUP(LEFT('1) Import fichier Remi (coller)'!$A7,9),'Concordance client liv et fact'!$A:$H,8,FALSE))=TRUE,VLOOKUP(LEFT('1) Import fichier Remi (coller)'!$A7,9)+0,'Clients R2'!$A:$CY,102,FALSE),VLOOKUP(VLOOKUP(LEFT('1) Import fichier Remi (coller)'!$A7,9),'Concordance client liv et fact'!$A:$H,7,FALSE)+0,'Clients R2'!$A:$CY,102,FALSE))) -> compta.ibs@ibgraf.com | Y7: CF11261601.PDF | Z7: GDUHOUX | AA7: =IF($A7="VE11","",IF(LEFT($H7,4)="7050","",IF('1) Import fichier Remi (coller)'!M7="","",'1) Import fichier Remi (coller)'!M7))) | AB7: =IF($A7="VE11","",IF(LEFT($H7,4)="7050","",IF('1) Import fichier Remi (coller)'!N7="","",'1) Import fichier Remi (coller)'!N7))) | AC7: =IF(A7="","",VLOOKUP(LEFT('1) Import fichier Remi (coller)'!A7,9)+0,'Concordance Client R2 BOB'!$B:$C,2,FALSE)) -> IBS
A8: =IF('1) Import fichier Remi (coller)'!D8="","",'1) Import fichier Remi (coller)'!D8) -> VE11 | B8: =IF(A8="","",YEAR('1) Import fichier Remi (coller)'!F8)) -> 2026 | C8: =IF(A8="","",MONTH('1) Import fichier Remi (coller)'!F8)) -> 9 | D8: =IF(A8="","",'1) Import fichier Remi (coller)'!F8) -> 46281 | E8: =IF(A8="","",'1) Import fichier Remi (coller)'!G8) -> 46281 | F8: =IF(A8="","",'1) Import fichier Remi (coller)'!E8) -> 11261512 | G8: =IF(A8="","",IF(ISERROR(VLOOKUP(LEFT('1) Import fichier Remi (coller)'!A8,9),'Concordance client liv et fact'!$A:$H,8,FALSE))=TRUE,'1) Import fichier Remi (coller)'!B8,VLOOKUP(LEFT('1) Import fichier Remi (coller)'!A8,9),'Concordance client liv et fact'!$A:$H,8,FALSE))) -> CBFISC | H8: =IF(A8="","",IF(ISERROR(VLOOKUP('1) Import fichier Remi (coller)'!K8&" - "&'1) Import fichier Remi (coller)'!L8,'Spécifique comptes'!$A:$G,1,FALSE))=TRUE,'1) Import fichier Remi (coller)'!V8,VLOOKUP('1) Import fichier Remi (coller)'!K8&" - "&'1) Import fichier Remi (coller)'!L8,'Spécifique comptes'!$A:$G,IF(LEFT('2) BOB compta (completer-forcer'!F8,2)="11",4,IF(LEFT('2) BOB compta (completer-forcer'!F8,2)="12",5,IF(LEFT('2) BOB compta (completer-forcer'!F8,2)="13",6,IF(LEFT('2) BOB compta (completer-forcer'!F8,2)="15",7,"Erreur Compte")))),FALSE))) -> 705099999 | I8: =IF(A8="","",IF(H8="70100000",'1) Import fichier Remi (coller)'!J8,'1) Import fichier Remi (coller)'!U8)) -> +++003/7261/51229+++ | J8: =IF(A8="","",'1) Import fichier Remi (coller)'!U8) -> +++003/7261/51229+++ | K8: =IF(A8="","",SUMIFS(N:N,A:A,A8,F:F,F8)+SUMIFS(O:O,A:A,A8,F:F,F8)) -> 28.74 | L8: =IF(A8="","",IF(LEFT(T8,1)="B","V","PRT")) -> V | M8: =IF(A8="","",'1) Import fichier Remi (coller)'!S8) -> 21 | N8: =IF($A8="","",IF(OR($A8="NCV",$A8="NC15"),-'1) Import fichier Remi (coller)'!R8,'1) Import fichier Remi (coller)'!R8)) -> 23.75 | O8: =IF($A8="","",IF(OR($A8="NCV",$A8="NC15"),-'1) Import fichier Remi (coller)'!T8,'1) Import fichier Remi (coller)'!T8)) -> 4.99 | R8: =IF($A8="","",IF(ISERROR(VLOOKUP(LEFT('1) Import fichier Remi (coller)'!$A8,9),'Concordance client liv et fact'!$A:$H,8,FALSE))=TRUE,VLOOKUP(LEFT('1) Import fichier Remi (coller)'!$A8,9)+0,'Clients R2'!$A:$CY,2,FALSE),VLOOKUP(VLOOKUP(LEFT('1) Import fichier Remi (coller)'!$A8,9),'Concordance client liv et fact'!$A:$H,7,FALSE)+0,'Clients R2'!$A:$CY,2,FALSE))) -> CB FISC | S8: =IF($A8="","",PROPER(IF(ISERROR(VLOOKUP(LEFT('1) Import fichier Remi (coller)'!$A8,9),'Concordance client liv et fact'!$A:$H,8,FALSE))=TRUE,VLOOKUP(LEFT('1) Import fichier Remi (coller)'!$A8,9)+0,'Clients R2'!$A:$CY,27,FALSE),VLOOKUP(VLOOKUP(LEFT('1) Import fichier Remi (coller)'!$A8,9),'Concordance client liv et fact'!$A:$H,7,FALSE)+0,'Clients R2'!$A:$CY,27,FALSE)))) -> Rue Affnay, 13 | T8: =IF($A8="","",LEFT(UPPER(IF(ISERROR(VLOOKUP(LEFT('1) Import fichier Remi (coller)'!$A8,9),'Concordance client liv et fact'!$A:$H,8,FALSE))=TRUE,VLOOKUP(LEFT('1) Import fichier Remi (coller)'!$A8,9)+0,'Clients R2'!$A:$CY,28,FALSE),VLOOKUP(VLOOKUP(LEFT('1) Import fichier Remi (coller)'!$A8,9),'Concordance client liv et fact'!$A:$H,7,FALSE)+0,'Clients R2'!$A:$CY,28,FALSE))),2)&UPPER(IF(ISERROR(VLOOKUP(LEFT('1) Import fichier Remi (coller)'!$A8,9),'Concordance client liv et fact'!$A:$H,8,FALSE))=TRUE,VLOOKUP(LEFT('1) Import fichier Remi (coller)'!$A8,9)+0,'Clients R2'!$A:$CY,29,FALSE),VLOOKUP(VLOOKUP(LEFT('1) Import fichier Remi (coller)'!$A8,9),'Concordance client liv et fact'!$A:$H,7,FALSE)+0,'Clients R2'!$A:$CY,29,FALSE)))) -> B 4608 | U8: =IF($A8="","",PROPER(IF(ISERROR(VLOOKUP(LEFT('1) Import fichier Remi (coller)'!$A8,9),'Concordance client liv et fact'!$A:$H,8,FALSE))=TRUE,VLOOKUP(LEFT('1) Import fichier Remi (coller)'!$A8,9)+0,'Clients R2'!$A:$CY,30,FALSE),VLOOKUP(VLOOKUP(LEFT('1) Import fichier Remi (coller)'!$A8,9),'Concordance client liv et fact'!$A:$H,7,FALSE)+0,'Clients R2'!$A:$CY,30,FALSE)))) -> Dalhem (Neufchateau) | V8: =IF($A8="","",LEFT(UPPER(IF(ISERROR(VLOOKUP(LEFT('1) Import fichier Remi (coller)'!$A8,9),'Concordance client liv et fact'!$A:$H,8,FALSE))=TRUE,IF(VLOOKUP(LEFT('1) Import fichier Remi (coller)'!$A8,9)+0,'Clients R2'!$A:$CY,22,FALSE)=4,"NA",VLOOKUP(LEFT('1) Import fichier Remi (coller)'!$A8,9)+0,'Clients R2'!$A:$CY,3,FALSE)),IF(VLOOKUP(VLOOKUP(LEFT('1) Import fichier Remi (coller)'!$A8,9),'Concordance client liv et fact'!$A:$H,7,FALSE)+0,'Clients R2'!$A:$CY,22,FALSE)=4,"NA",VLOOKUP(VLOOKUP(LEFT('1) Import fichier Remi (coller)'!$A8,9),'Concordance client liv et fact'!$A:$H,7,FALSE)+0,'Clients R2'!$A:$CY,3,FALSE)))),2)) -> BE | X8: =IF($A8="","",IF(ISERROR(VLOOKUP(LEFT('1) Import fichier Remi (coller)'!$A8,9),'Concordance client liv et fact'!$A:$H,8,FALSE))=TRUE,VLOOKUP(LEFT('1) Import fichier Remi (coller)'!$A8,9)+0,'Clients R2'!$A:$CY,102,FALSE),VLOOKUP(VLOOKUP(LEFT('1) Import fichier Remi (coller)'!$A8,9),'Concordance client liv et fact'!$A:$H,7,FALSE)+0,'Clients R2'!$A:$CY,102,FALSE))) -> info@cbfisc.be | Y8: CF11261601.PDF | Z8: =IF(A8="","",IF(OR(H8="705099999",H8="705001002"),VLOOKUP('1) Import fichier Remi (coller)'!J8,'Analytique personnel'!$A:$B,2,FALSE),"")) -> GDUHOUX | AA8: =IF($A8="VE11","",IF(LEFT($H8,4)="7050","",IF('1) Import fichier Remi (coller)'!M8="","",'1) Import fichier Remi (coller)'!M8))) | AB8: =IF($A8="VE11","",IF(LEFT($H8,4)="7050","",IF('1) Import fichier Remi (coller)'!N8="","",'1) Import fichier Remi (coller)'!N8))) | AC8: =IF(A8="","",VLOOKUP(LEFT('1) Import fichier Remi (coller)'!A8,9)+0,'Concordance Client R2 BOB'!$B:$C,2,FALSE)) -> CBFISC
A9: =IF('1) Import fichier Remi (coller)'!D9="","",'1) Import fichier Remi (coller)'!D9) -> VE11 | B9: =IF(A9="","",YEAR('1) Import fichier Remi (coller)'!F9)) -> 2026 | C9: =IF(A9="","",MONTH('1) Import fichier Remi (coller)'!F9)) -> 9 | D9: =IF(A9="","",'1) Import fichier Remi (coller)'!F9) -> 46281 | E9: =IF(A9="","",'1) Import fichier Remi (coller)'!G9) -> 46311 | F9: =IF(A9="","",'1) Import fichier Remi (coller)'!E9) -> 11261513 | G9: =IF(A9="","",IF(ISERROR(VLOOKUP(LEFT('1) Import fichier Remi (coller)'!A9,9),'Concordance client liv et fact'!$A:$H,8,FALSE))=TRUE,'1) Import fichier Remi (coller)'!B9,VLOOKUP(LEFT('1) Import fichier Remi (coller)'!A9,9),'Concordance client liv et fact'!$A:$H,8,FALSE))) -> COUTREZSA | H9: =IF(A9="","",IF(ISERROR(VLOOKUP('1) Import fichier Remi (coller)'!K9&" - "&'1) Import fichier Remi (coller)'!L9,'Spécifique comptes'!$A:$G,1,FALSE))=TRUE,'1) Import fichier Remi (coller)'!V9,VLOOKUP('1) Import fichier Remi (coller)'!K9&" - "&'1) Import fichier Remi (coller)'!L9,'Spécifique comptes'!$A:$G,IF(LEFT('2) BOB compta (completer-forcer'!F9,2)="11",4,IF(LEFT('2) BOB compta (completer-forcer'!F9,2)="12",5,IF(LEFT('2) BOB compta (completer-forcer'!F9,2)="13",6,IF(LEFT('2) BOB compta (completer-forcer'!F9,2)="15",7,"Erreur Compte")))),FALSE))) -> 705099999 | I9: =IF(A9="","",IF(H9="70100000",'1) Import fichier Remi (coller)'!J9,'1) Import fichier Remi (coller)'!U9)) -> +++003/7261/51330+++ | J9: =IF(A9="","",'1) Import fichier Remi (coller)'!U9) -> +++003/7261/51330+++ | K9: =IF(A9="","",SUMIFS(N:N,A:A,A9,F:F,F9)+SUMIFS(O:O,A:A,A9,F:F,F9)) -> 114.95 | L9: =IF(A9="","",IF(LEFT(T9,1)="B","V","PRT")) -> V | M9: =IF(A9="","",'1) Import fichier Remi (coller)'!S9) -> 21 | N9: =IF($A9="","",IF(OR($A9="NCV",$A9="NC15"),-'1) Import fichier Remi (coller)'!R9,'1) Import fichier Remi (coller)'!R9)) -> 95 | O9: =IF($A9="","",IF(OR($A9="NCV",$A9="NC15"),-'1) Import fichier Remi (coller)'!T9,'1) Import fichier Remi (coller)'!T9)) -> 19.95 | R9: =IF($A9="","",IF(ISERROR(VLOOKUP(LEFT('1) Import fichier Remi (coller)'!$A9,9),'Concordance client liv et fact'!$A:$H,8,FALSE))=TRUE,VLOOKUP(LEFT('1) Import fichier Remi (coller)'!$A9,9)+0,'Clients R2'!$A:$CY,2,FALSE),VLOOKUP(VLOOKUP(LEFT('1) Import fichier Remi (coller)'!$A9,9),'Concordance client liv et fact'!$A:$H,7,FALSE)+0,'Clients R2'!$A:$CY,2,FALSE))) -> ETS COUTREZ ET CIE SA | S9: =IF($A9="","",PROPER(IF(ISERROR(VLOOKUP(LEFT('1) Import fichier Remi (coller)'!$A9,9),'Concordance client liv et fact'!$A:$H,8,FALSE))=TRUE,VLOOKUP(LEFT('1) Import fichier Remi (coller)'!$A9,9)+0,'Clients R2'!$A:$CY,27,FALSE),VLOOKUP(VLOOKUP(LEFT('1) Import fichier Remi (coller)'!$A9,9),'Concordance client liv et fact'!$A:$H,7,FALSE)+0,'Clients R2'!$A:$CY,27,FALSE)))) -> Rue Louis Bleriot, 1 | T9: =IF($A9="","",LEFT(UPPER(IF(ISERROR(VLOOKUP(LEFT('1) Import fichier Remi (coller)'!$A9,9),'Concordance client liv et fact'!$A:$H,8,FALSE))=TRUE,VLOOKUP(LEFT('1) Import fichier Remi (coller)'!$A9,9)+0,'Clients R2'!$A:$CY,28,FALSE),VLOOKUP(VLOOKUP(LEFT('1) Import fichier Remi (coller)'!$A9,9),'Concordance client liv et fact'!$A:$H,7,FALSE)+0,'Clients R2'!$A:$CY,28,FALSE))),2)&UPPER(IF(ISERROR(VLOOKUP(LEFT('1) Import fichier Remi (coller)'!$A9,9),'Concordance client liv et fact'!$A:$H,8,FALSE))=TRUE,VLOOKUP(LEFT('1) Import fichier Remi (coller)'!$A9,9)+0,'Clients R2'!$A:$CY,29,FALSE),VLOOKUP(VLOOKUP(LEFT('1) Import fichier Remi (coller)'!$A9,9),'Concordance client liv et fact'!$A:$H,7,FALSE)+0,'Clients R2'!$A:$CY,29,FALSE)))) -> B 4460 | U9: =IF($A9="","",PROPER(IF(ISERROR(VLOOKUP(LEFT('1) Import fichier Remi (coller)'!$A9,9),'Concordance client liv et fact'!$A:$H,8,FALSE))=TRUE,VLOOKUP(LEFT('1) Import fichier Remi (coller)'!$A9,9)+0,'Clients R2'!$A:$CY,30,FALSE),VLOOKUP(VLOOKUP(LEFT('1) Import fichier Remi (coller)'!$A9,9),'Concordance client liv et fact'!$A:$H,7,FALSE)+0,'Clients R2'!$A:$CY,30,FALSE)))) -> Grace Hollogne | V9: =IF($A9="","",LEFT(UPPER(IF(ISERROR(VLOOKUP(LEFT('1) Import fichier Remi (coller)'!$A9,9),'Concordance client liv et fact'!$A:$H,8,FALSE))=TRUE,IF(VLOOKUP(LEFT('1) Import fichier Remi (coller)'!$A9,9)+0,'Clients R2'!$A:$CY,22,FALSE)=4,"NA",VLOOKUP(LEFT('1) Import fichier Remi (coller)'!$A9,9)+0,'Clients R2'!$A:$CY,3,FALSE)),IF(VLOOKUP(VLOOKUP(LEFT('1) Import fichier Remi (coller)'!$A9,9),'Concordance client liv et fact'!$A:$H,7,FALSE)+0,'Clients R2'!$A:$CY,22,FALSE)=4,"NA",VLOOKUP(VLOOKUP(LEFT('1) Import fichier Remi (coller)'!$A9,9),'Concordance client liv et fact'!$A:$H,7,FALSE)+0,'Clients R2'!$A:$CY,3,FALSE)))),2)) -> BE | X9: =IF($A9="","",IF(ISERROR(VLOOKUP(LEFT('1) Import fichier Remi (coller)'!$A9,9),'Concordance client liv et fact'!$A:$H,8,FALSE))=TRUE,VLOOKUP(LEFT('1) Import fichier Remi (coller)'!$A9,9)+0,'Clients R2'!$A:$CY,102,FALSE),VLOOKUP(VLOOKUP(LEFT('1) Import fichier Remi (coller)'!$A9,9),'Concordance client liv et fact'!$A:$H,7,FALSE)+0,'Clients R2'!$A:$CY,102,FALSE))) -> invoicing@coutrez.be | Y9: CF11261601.PDF | Z9: =IF(A9="","",IF(OR(H9="705099999",H9="705001002"),VLOOKUP('1) Import fichier Remi (coller)'!J9,'Analytique personnel'!$A:$B,2,FALSE),"")) -> BMELIN | AA9: =IF($A9="VE11","",IF(LEFT($H9,4)="7050","",IF('1) Import fichier Remi (coller)'!M9="","",'1) Import fichier Remi (coller)'!M9))) | AB9: =IF($A9="VE11","",IF(LEFT($H9,4)="7050","",IF('1) Import fichier Remi (coller)'!N9="","",'1) Import fichier Remi (coller)'!N9))) | AC9: =IF(A9="","",VLOOKUP(LEFT('1) Import fichier Remi (coller)'!A9,9)+0,'Concordance Client R2 BOB'!$B:$C,2,FALSE)) -> COUTREZSA
A10: =IF('1) Import fichier Remi (coller)'!D10="","",'1) Import fichier Remi (coller)'!D10) -> VE11 | B10: =IF(A10="","",YEAR('1) Import fichier Remi (coller)'!F10)) -> 2026 | C10: =IF(A10="","",MONTH('1) Import fichier Remi (coller)'!F10)) -> 9 | D10: =IF(A10="","",'1) Import fichier Remi (coller)'!F10) -> 46281 | E10: =IF(A10="","",'1) Import fichier Remi (coller)'!G10) -> 46281 | F10: =IF(A10="","",'1) Import fichier Remi (coller)'!E10) -> 11261514 | G10: =IF(A10="","",IF(ISERROR(VLOOKUP(LEFT('1) Import fichier Remi (coller)'!A10,9),'Concordance client liv et fact'!$A:$H,8,FALSE))=TRUE,'1) Import fichier Remi (coller)'!B10,VLOOKUP(LEFT('1) Import fichier Remi (coller)'!A10,9),'Concordance client liv et fact'!$A:$H,8,FALSE))) -> DEL003 | H10: =IF(A10="","",IF(ISERROR(VLOOKUP('1) Import fichier Remi (coller)'!K10&" - "&'1) Import fichier Remi (coller)'!L10,'Spécifique comptes'!$A:$G,1,FALSE))=TRUE,'1) Import fichier Remi (coller)'!V10,VLOOKUP('1) Import fichier Remi (coller)'!K10&" - "&'1) Import fichier Remi (coller)'!L10,'Spécifique comptes'!$A:$G,IF(LEFT('2) BOB compta (completer-forcer'!F10,2)="11",4,IF(LEFT('2) BOB compta (completer-forcer'!F10,2)="12",5,IF(LEFT('2) BOB compta (completer-forcer'!F10,2)="13",6,IF(LEFT('2) BOB compta (completer-forcer'!F10,2)="15",7,"Erreur Compte")))),FALSE))) -> 705099999 | I10: =IF(A10="","",IF(H10="70100000",'1) Import fichier Remi (coller)'!J10,'1) Import fichier Remi (coller)'!U10)) -> +++003/7261/51431+++ | J10: =IF(A10="","",'1) Import fichier Remi (coller)'!U10) -> +++003/7261/51431+++ | K10: =IF(A10="","",SUMIFS(N:N,A:A,A10,F:F,F10)+SUMIFS(O:O,A:A,A10,F:F,F10)) -> 205.46 | L10: =IF(A10="","",IF(LEFT(T10,1)="B","V","PRT")) -> V | M10: =IF(A10="","",'1) Import fichier Remi (coller)'!S10) -> 21 | N10: =IF($A10="","",IF(OR($A10="NCV",$A10="NC15"),-'1) Import fichier Remi (coller)'!R10,'1) Import fichier Remi (coller)'!R10)) -> 47.5 | O10: =IF($A10="","",IF(OR($A10="NCV",$A10="NC15"),-'1) Import fichier Remi (coller)'!T10,'1) Import fichier Remi (coller)'!T10)) -> 9.98 | R10: =IF($A10="","",IF(ISERROR(VLOOKUP(LEFT('1) Import fichier Remi (coller)'!$A10,9),'Concordance client liv et fact'!$A:$H,8,FALSE))=TRUE,VLOOKUP(LEFT('1) Import fichier Remi (coller)'!$A10,9)+0,'Clients R2'!$A:$CY,2,FALSE),VLOOKUP(VLOOKUP(LEFT('1) Import fichier Remi (coller)'!$A10,9),'Concordance client liv et fact'!$A:$H,7,FALSE)+0,'Clients R2'!$A:$CY,2,FALSE))) -> DELHEZ COMBUSTIBLES | S10: =IF($A10="","",PROPER(IF(ISERROR(VLOOKUP(LEFT('1) Import fichier Remi (coller)'!$A10,9),'Concordance client liv et fact'!$A:$H,8,FALSE))=TRUE,VLOOKUP(LEFT('1) Import fichier Remi (coller)'!$A10,9)+0,'Clients R2'!$A:$CY,27,FALSE),VLOOKUP(VLOOKUP(LEFT('1) Import fichier Remi (coller)'!$A10,9),'Concordance client liv et fact'!$A:$H,7,FALSE)+0,'Clients R2'!$A:$CY,27,FALSE)))) -> Route Du Chateau, 4 | T10: =IF($A10="","",LEFT(UPPER(IF(ISERROR(VLOOKUP(LEFT('1) Import fichier Remi (coller)'!$A10,9),'Concordance client liv et fact'!$A:$H,8,FALSE))=TRUE,VLOOKUP(LEFT('1) Import fichier Remi (coller)'!$A10,9)+0,'Clients R2'!$A:$CY,28,FALSE),VLOOKUP(VLOOKUP(LEFT('1) Import fichier Remi (coller)'!$A10,9),'Concordance client liv et fact'!$A:$H,7,FALSE)+0,'Clients R2'!$A:$CY,28,FALSE))),2)&UPPER(IF(ISERROR(VLOOKUP(LEFT('1) Import fichier Remi (coller)'!$A10,9),'Concordance client liv et fact'!$A:$H,8,FALSE))=TRUE,VLOOKUP(LEFT('1) Import fichier Remi (coller)'!$A10,9)+0,'Clients R2'!$A:$CY,29,FALSE),VLOOKUP(VLOOKUP(LEFT('1) Import fichier Remi (coller)'!$A10,9),'Concordance client liv et fact'!$A:$H,7,FALSE)+0,'Clients R2'!$A:$CY,29,FALSE)))) -> B 4877 | U10: =IF($A10="","",PROPER(IF(ISERROR(VLOOKUP(LEFT('1) Import fichier Remi (coller)'!$A10,9),'Concordance client liv et fact'!$A:$H,8,FALSE))=TRUE,VLOOKUP(LEFT('1) Import fichier Remi (coller)'!$A10,9)+0,'Clients R2'!$A:$CY,30,FALSE),VLOOKUP(VLOOKUP(LEFT('1) Import fichier Remi (coller)'!$A10,9),'Concordance client liv et fact'!$A:$H,7,FALSE)+0,'Clients R2'!$A:$CY,30,FALSE)))) -> Olne | V10: =IF($A10="","",LEFT(UPPER(IF(ISERROR(VLOOKUP(LEFT('1) Import fichier Remi (coller)'!$A10,9),'Concordance client liv et fact'!$A:$H,8,FALSE))=TRUE,IF(VLOOKUP(LEFT('1) Import fichier Remi (coller)'!$A10,9)+0,'Clients R2'!$A:$CY,22,FALSE)=4,"NA",VLOOKUP(LEFT('1) Import fichier Remi (coller)'!$A10,9)+0,'Clients R2'!$A:$CY,3,FALSE)),IF(VLOOKUP(VLOOKUP(LEFT('1) Import fichier Remi (coller)'!$A10,9),'Concordance client liv et fact'!$A:$H,7,FALSE)+0,'Clients R2'!$A:$CY,22,FALSE)=4,"NA",VLOOKUP(VLOOKUP(LEFT('1) Import fichier Remi (coller)'!$A10,9),'Concordance client liv et fact'!$A:$H,7,FALSE)+0,'Clients R2'!$A:$CY,3,FALSE)))),2)) -> BE | X10: =IF($A10="","",IF(ISERROR(VLOOKUP(LEFT('1) Import fichier Remi (coller)'!$A10,9),'Concordance client liv et fact'!$A:$H,8,FALSE))=TRUE,VLOOKUP(LEFT('1) Import fichier Remi (coller)'!$A10,9)+0,'Clients R2'!$A:$CY,102,FALSE),VLOOKUP(VLOOKUP(LEFT('1) Import fichier Remi (coller)'!$A10,9),'Concordance client liv et fact'!$A:$H,7,FALSE)+0,'Clients R2'!$A:$CY,102,FALSE))) -> info@delhez-combustibles.be | Y10: CF11261601.PDF | Z10: =IF(A10="","",IF(OR(H10="705099999",H10="705001002"),VLOOKUP('1) Import fichier Remi (coller)'!J10,'Analytique personnel'!$A:$B,2,FALSE),"")) -> MFONTAINE | AA10: =IF($A10="VE11","",IF(LEFT($H10,4)="7050","",IF('1) Import fichier Remi (coller)'!M10="","",'1) Import fichier Remi (coller)'!M10))) | AB10: =IF($A10="VE11","",IF(LEFT($H10,4)="7050","",IF('1) Import fichier Remi (coller)'!N10="","",'1) Import fichier Remi (coller)'!N10))) | AC10: =IF(A10="","",VLOOKUP(LEFT('1) Import fichier Remi (coller)'!A10,9)+0,'Concordance Client R2 BOB'!$B:$C,2,FALSE)) -> DEL003
A11: =IF('1) Import fichier Remi (coller)'!D11="","",'1) Import fichier Remi (coller)'!D11) -> VE11 | B11: =IF(A11="","",YEAR('1) Import fichier Remi (coller)'!F11)) -> 2026 | C11: =IF(A11="","",MONTH('1) Import fichier Remi (coller)'!F11)) -> 9 | D11: =IF(A11="","",'1) Import fichier Remi (coller)'!F11) -> 46281 | E11: =IF(A11="","",'1) Import fichier Remi (coller)'!G11) -> 46281 | F11: =IF(A11="","",'1) Import fichier Remi (coller)'!E11) -> 11261514 | G11: =IF(A11="","",IF(ISERROR(VLOOKUP(LEFT('1) Import fichier Remi (coller)'!A11,9),'Concordance client liv et fact'!$A:$H,8,FALSE))=TRUE,'1) Import fichier Remi (coller)'!B11,VLOOKUP(LEFT('1) Import fichier Remi (coller)'!A11,9),'Concordance client liv et fact'!$A:$H,8,FALSE))) -> DEL003 | H11: =IF(A11="","",IF(ISERROR(VLOOKUP('1) Import fichier Remi (coller)'!K11&" - "&'1) Import fichier Remi (coller)'!L11,'Spécifique comptes'!$A:$G,1,FALSE))=TRUE,'1) Import fichier Remi (coller)'!V11,VLOOKUP('1) Import fichier Remi (coller)'!K11&" - "&'1) Import fichier Remi (coller)'!L11,'Spécifique comptes'!$A:$G,IF(LEFT('2) BOB compta (completer-forcer'!F11,2)="11",4,IF(LEFT('2) BOB compta (completer-forcer'!F11,2)="12",5,IF(LEFT('2) BOB compta (completer-forcer'!F11,2)="13",6,IF(LEFT('2) BOB compta (completer-forcer'!F11,2)="15",7,"Erreur Compte")))),FALSE))) -> 705099999 | I11: =IF(A11="","",IF(H11="70100000",'1) Import fichier Remi (coller)'!J11,'1) Import fichier Remi (coller)'!U11)) -> +++003/7261/51431+++ | J11: =IF(A11="","",'1) Import fichier Remi (coller)'!U11) -> +++003/7261/51431+++ | K11: =IF(A11="","",SUMIFS(N:N,A:A,A11,F:F,F11)+SUMIFS(O:O,A:A,A11,F:F,F11)) -> 205.46 | L11: =IF(A11="","",IF(LEFT(T11,1)="B","V","PRT")) -> V | M11: =IF(A11="","",'1) Import fichier Remi (coller)'!S11) -> 21 | N11: =IF($A11="","",IF(OR($A11="NCV",$A11="NC15"),-'1) Import fichier Remi (coller)'!R11,'1) Import fichier Remi (coller)'!R11)) -> 47.5 | O11: =IF($A11="","",IF(OR($A11="NCV",$A11="NC15"),-'1) Import fichier Remi (coller)'!T11,'1) Import fichier Remi (coller)'!T11)) -> 9.98 | R11: =IF($A11="","",IF(ISERROR(VLOOKUP(LEFT('1) Import fichier Remi (coller)'!$A11,9),'Concordance client liv et fact'!$A:$H,8,FALSE))=TRUE,VLOOKUP(LEFT('1) Import fichier Remi (coller)'!$A11,9)+0,'Clients R2'!$A:$CY,2,FALSE),VLOOKUP(VLOOKUP(LEFT('1) Import fichier Remi (coller)'!$A11,9),'Concordance client liv et fact'!$A:$H,7,FALSE)+0,'Clients R2'!$A:$CY,2,FALSE))) -> DELHEZ COMBUSTIBLES | S11: =IF($A11="","",PROPER(IF(ISERROR(VLOOKUP(LEFT('1) Import fichier Remi (coller)'!$A11,9),'Concordance client liv et fact'!$A:$H,8,FALSE))=TRUE,VLOOKUP(LEFT('1) Import fichier Remi (coller)'!$A11,9)+0,'Clients R2'!$A:$CY,27,FALSE),VLOOKUP(VLOOKUP(LEFT('1) Import fichier Remi (coller)'!$A11,9),'Concordance client liv et fact'!$A:$H,7,FALSE)+0,'Clients R2'!$A:$CY,27,FALSE)))) -> Route Du Chateau, 4 | T11: =IF($A11="","",LEFT(UPPER(IF(ISERROR(VLOOKUP(LEFT('1) Import fichier Remi (coller)'!$A11,9),'Concordance client liv et fact'!$A:$H,8,FALSE))=TRUE,VLOOKUP(LEFT('1) Import fichier Remi (coller)'!$A11,9)+0,'Clients R2'!$A:$CY,28,FALSE),VLOOKUP(VLOOKUP(LEFT('1) Import fichier Remi (coller)'!$A11,9),'Concordance client liv et fact'!$A:$H,7,FALSE)+0,'Clients R2'!$A:$CY,28,FALSE))),2)&UPPER(IF(ISERROR(VLOOKUP(LEFT('1) Import fichier Remi (coller)'!$A11,9),'Concordance client liv et fact'!$A:$H,8,FALSE))=TRUE,VLOOKUP(LEFT('1) Import fichier Remi (coller)'!$A11,9)+0,'Clients R2'!$A:$CY,29,FALSE),VLOOKUP(VLOOKUP(LEFT('1) Import fichier Remi (coller)'!$A11,9),'Concordance client liv et fact'!$A:$H,7,FALSE)+0,'Clients R2'!$A:$CY,29,FALSE)))) -> B 4877 | U11: =IF($A11="","",PROPER(IF(ISERROR(VLOOKUP(LEFT('1) Import fichier Remi (coller)'!$A11,9),'Concordance client liv et fact'!$A:$H,8,FALSE))=TRUE,VLOOKUP(LEFT('1) Import fichier Remi (coller)'!$A11,9)+0,'Clients R2'!$A:$CY,30,FALSE),VLOOKUP(VLOOKUP(LEFT('1) Import fichier Remi (coller)'!$A11,9),'Concordance client liv et fact'!$A:$H,7,FALSE)+0,'Clients R2'!$A:$CY,30,FALSE)))) -> Olne | V11: =IF($A11="","",LEFT(UPPER(IF(ISERROR(VLOOKUP(LEFT('1) Import fichier Remi (coller)'!$A11,9),'Concordance client liv et fact'!$A:$H,8,FALSE))=TRUE,IF(VLOOKUP(LEFT('1) Import fichier Remi (coller)'!$A11,9)+0,'Clients R2'!$A:$CY,22,FALSE)=4,"NA",VLOOKUP(LEFT('1) Import fichier Remi (coller)'!$A11,9)+0,'Clients R2'!$A:$CY,3,FALSE)),IF(VLOOKUP(VLOOKUP(LEFT('1) Import fichier Remi (coller)'!$A11,9),'Concordance client liv et fact'!$A:$H,7,FALSE)+0,'Clients R2'!$A:$CY,22,FALSE)=4,"NA",VLOOKUP(VLOOKUP(LEFT('1) Import fichier Remi (coller)'!$A11,9),'Concordance client liv et fact'!$A:$H,7,FALSE)+0,'Clients R2'!$A:$CY,3,FALSE)))),2)) -> BE | X11: =IF($A11="","",IF(ISERROR(VLOOKUP(LEFT('1) Import fichier Remi (coller)'!$A11,9),'Concordance client liv et fact'!$A:$H,8,FALSE))=TRUE,VLOOKUP(LEFT('1) Import fichier Remi (coller)'!$A11,9)+0,'Clients R2'!$A:$CY,102,FALSE),VLOOKUP(VLOOKUP(LEFT('1) Import fichier Remi (coller)'!$A11,9),'Concordance client liv et fact'!$A:$H,7,FALSE)+0,'Clients R2'!$A:$CY,102,FALSE))) -> info@delhez-combustibles.be | Y11: CF11261601.PDF | Z11: =IF(A11="","",IF(OR(H11="705099999",H11="705001002"),VLOOKUP('1) Import fichier Remi (coller)'!J11,'Analytique personnel'!$A:$B,2,FALSE),"")) -> GDUHOUX | AA11: =IF($A11="VE11","",IF(LEFT($H11,4)="7050","",IF('1) Import fichier Remi (coller)'!M11="","",'1) Import fichier Remi (coller)'!M11))) | AB11: =IF($A11="VE11","",IF(LEFT($H11,4)="7050","",IF('1) Import fichier Remi (coller)'!N11="","",'1) Import fichier Remi (coller)'!N11))) | AC11: =IF(A11="","",VLOOKUP(LEFT('1) Import fichier Remi (coller)'!A11,9)+0,'Concordance Client R2 BOB'!$B:$C,2,FALSE)) -> DEL003
